[2023-11-29T21:43:02.561+0500] {taskinstance.py:1159} INFO - Dependencies all met for dep_context=non-requeueable deps ti=<TaskInstance: youtube_comments_score.get_data manual__2023-11-29T16:41:13.558987+00:00 [queued]>
[2023-11-29T21:43:02.614+0500] {taskinstance.py:1159} INFO - Dependencies all met for dep_context=requeueable deps ti=<TaskInstance: youtube_comments_score.get_data manual__2023-11-29T16:41:13.558987+00:00 [queued]>
[2023-11-29T21:43:02.617+0500] {taskinstance.py:1361} INFO - Starting attempt 1 of 2
[2023-11-29T21:43:02.745+0500] {taskinstance.py:1382} INFO - Executing <Task(BashOperator): get_data> on 2023-11-29 16:41:13.558987+00:00
[2023-11-29T21:43:02.761+0500] {standard_task_runner.py:57} INFO - Started process 9202 to run task
[2023-11-29T21:43:02.855+0500] {standard_task_runner.py:84} INFO - Running: ['airflow', 'tasks', 'run', 'youtube_comments_score', 'get_data', 'manual__2023-11-29T16:41:13.558987+00:00', '--job-id', '37', '--raw', '--subdir', 'DAGS_FOLDER/youtube_comments_score.py', '--cfg-path', '/tmp/tmpqxcsi1lx']
[2023-11-29T21:43:02.896+0500] {standard_task_runner.py:85} INFO - Job 37: Subtask get_data
[2023-11-29T21:43:04.273+0500] {task_command.py:416} INFO - Running <TaskInstance: youtube_comments_score.get_data manual__2023-11-29T16:41:13.558987+00:00 [running]> on host mlops
[2023-11-29T21:43:05.339+0500] {taskinstance.py:1662} INFO - Exporting env vars: AIRFLOW_CTX_DAG_OWNER='admin' AIRFLOW_CTX_DAG_ID='youtube_comments_score' AIRFLOW_CTX_TASK_ID='get_data' AIRFLOW_CTX_EXECUTION_DATE='2023-11-29T16:41:13.558987+00:00' AIRFLOW_CTX_TRY_NUMBER='1' AIRFLOW_CTX_DAG_RUN_ID='manual__2023-11-29T16:41:13.558987+00:00'
[2023-11-29T21:43:05.344+0500] {subprocess.py:63} INFO - Tmp dir root location: /tmp
[2023-11-29T21:43:05.357+0500] {subprocess.py:75} INFO - Running command: ['/usr/bin/bash', '-c', 'python3 /home/akashy/staidg/scripts/get_data.py']
[2023-11-29T21:43:05.412+0500] {subprocess.py:86} INFO - Output:
[2023-11-29T21:44:02.464+0500] {local_task_job_runner.py:294} WARNING - State of this instance has been externally set to None. Terminating instance.
[2023-11-29T21:44:02.549+0500] {process_utils.py:131} INFO - Sending 15 to group 9202. PIDs of all processes in the group: [9218, 9202]
[2023-11-29T21:44:02.550+0500] {process_utils.py:86} INFO - Sending the signal 15 to group 9202
[2023-11-29T21:44:02.554+0500] {taskinstance.py:1632} ERROR - Received SIGTERM. Terminating subprocesses.
[2023-11-29T21:44:02.555+0500] {subprocess.py:104} INFO - Sending SIGTERM signal to process group
[2023-11-29T21:44:02.768+0500] {taskinstance.py:1937} ERROR - Task failed with exception
Traceback (most recent call last):
  File "/home/akashy/staidg/env/lib/python3.8/site-packages/airflow/operators/bash.py", line 201, in execute
    result = self.subprocess_hook.run_command(
  File "/home/akashy/staidg/env/lib/python3.8/site-packages/airflow/hooks/subprocess.py", line 91, in run_command
    for raw_line in iter(self.sub_process.stdout.readline, b""):
  File "/home/akashy/staidg/env/lib/python3.8/site-packages/airflow/models/taskinstance.py", line 1634, in signal_handler
    raise AirflowException("Task received SIGTERM signal")
airflow.exceptions.AirflowException: Task received SIGTERM signal
[2023-11-29T21:44:02.851+0500] {taskinstance.py:1400} INFO - Marking task as FAILED. dag_id=youtube_comments_score, task_id=get_data, execution_date=20231129T164113, start_date=20231129T164302, end_date=20231129T164402
[2023-11-29T21:44:03.020+0500] {standard_task_runner.py:104} ERROR - Failed to execute job 37 for task get_data ((psycopg2.errors.ForeignKeyViolation) insert or update on table "task_fail" violates foreign key constraint "task_fail_ti_fkey"
DETAIL:  Key (dag_id, task_id, run_id, map_index)=(youtube_comments_score, get_data, manual__2023-11-29T16:41:13.558987+00:00, -1) is not present in table "task_instance".

[SQL: INSERT INTO task_fail (task_id, dag_id, run_id, map_index, start_date, end_date, duration) VALUES (%(task_id)s, %(dag_id)s, %(run_id)s, %(map_index)s, %(start_date)s, %(end_date)s, %(duration)s) RETURNING task_fail.id]
[parameters: {'task_id': 'get_data', 'dag_id': 'youtube_comments_score', 'run_id': 'manual__2023-11-29T16:41:13.558987+00:00', 'map_index': -1, 'start_date': datetime.datetime(2023, 11, 29, 16, 43, 2, 564610, tzinfo=Timezone('UTC')), 'end_date': datetime.datetime(2023, 11, 29, 16, 44, 2, 849996, tzinfo=Timezone('UTC')), 'duration': 60}]
(Background on this error at: https://sqlalche.me/e/14/gkpj); 9202)
[2023-11-29T21:44:03.204+0500] {process_utils.py:79} INFO - Process psutil.Process(pid=9218, status='terminated', started='21:43:04') (9218) terminated with exit code None
[2023-11-29T21:44:03.208+0500] {process_utils.py:79} INFO - Process psutil.Process(pid=9202, status='terminated', exitcode=1, started='21:43:01') (9202) terminated with exit code 1
