[2023-11-29T21:40:00.539+0500] {taskinstance.py:1159} INFO - Dependencies all met for dep_context=non-requeueable deps ti=<TaskInstance: youtube_comments_score.get_data manual__2023-11-29T16:33:20.863892+00:00 [queued]>
[2023-11-29T21:40:00.631+0500] {taskinstance.py:1159} INFO - Dependencies all met for dep_context=requeueable deps ti=<TaskInstance: youtube_comments_score.get_data manual__2023-11-29T16:33:20.863892+00:00 [queued]>
[2023-11-29T21:40:00.632+0500] {taskinstance.py:1361} INFO - Starting attempt 2 of 2
[2023-11-29T21:40:00.850+0500] {taskinstance.py:1382} INFO - Executing <Task(BashOperator): get_data> on 2023-11-29 16:33:20.863892+00:00
[2023-11-29T21:40:00.984+0500] {standard_task_runner.py:57} INFO - Started process 8573 to run task
[2023-11-29T21:40:01.018+0500] {standard_task_runner.py:84} INFO - Running: ['airflow', 'tasks', 'run', 'youtube_comments_score', 'get_data', 'manual__2023-11-29T16:33:20.863892+00:00', '--job-id', '35', '--raw', '--subdir', 'DAGS_FOLDER/youtube_comments_score.py', '--cfg-path', '/tmp/tmpflv7286p']
[2023-11-29T21:40:01.058+0500] {standard_task_runner.py:85} INFO - Job 35: Subtask get_data
[2023-11-29T21:40:03.450+0500] {task_command.py:416} INFO - Running <TaskInstance: youtube_comments_score.get_data manual__2023-11-29T16:33:20.863892+00:00 [running]> on host mlops
[2023-11-29T21:40:05.914+0500] {taskinstance.py:1662} INFO - Exporting env vars: AIRFLOW_CTX_DAG_OWNER='admin' AIRFLOW_CTX_DAG_ID='youtube_comments_score' AIRFLOW_CTX_TASK_ID='get_data' AIRFLOW_CTX_EXECUTION_DATE='2023-11-29T16:33:20.863892+00:00' AIRFLOW_CTX_TRY_NUMBER='2' AIRFLOW_CTX_DAG_RUN_ID='manual__2023-11-29T16:33:20.863892+00:00'
[2023-11-29T21:40:05.934+0500] {subprocess.py:63} INFO - Tmp dir root location: /tmp
[2023-11-29T21:40:05.936+0500] {subprocess.py:75} INFO - Running command: ['/usr/bin/bash', '-c', 'python3 /home/akashy/staidg/scripts/get_data.py']
[2023-11-29T21:40:06.262+0500] {subprocess.py:86} INFO - Output:
[2023-11-29T21:41:17.461+0500] {subprocess.py:93} INFO - /home/akashy/staidg/env/lib/python3.8/site-packages/pydantic/_internal/_fields.py:149: UserWarning: Field "model_server_url" has conflict with protected namespace "model_".
[2023-11-29T21:41:17.463+0500] {subprocess.py:93} INFO - 
[2023-11-29T21:41:17.464+0500] {subprocess.py:93} INFO - You may be able to resolve this warning by setting `model_config['protected_namespaces'] = ()`.
[2023-11-29T21:41:17.465+0500] {subprocess.py:93} INFO -   warnings.warn(
[2023-11-29T21:41:17.466+0500] {subprocess.py:93} INFO - /home/akashy/staidg/env/lib/python3.8/site-packages/pydantic/_internal/_config.py:321: UserWarning: Valid config keys have changed in V2:
[2023-11-29T21:41:17.468+0500] {subprocess.py:93} INFO - * 'schema_extra' has been renamed to 'json_schema_extra'
[2023-11-29T21:41:17.469+0500] {subprocess.py:93} INFO -   warnings.warn(message, UserWarning)
[2023-11-29T21:41:17.470+0500] {subprocess.py:93} INFO - Traceback (most recent call last):
[2023-11-29T21:41:17.474+0500] {subprocess.py:93} INFO -   File "/home/akashy/staidg/env/lib/python3.8/site-packages/urllib3/connection.py", line 203, in _new_conn
[2023-11-29T21:41:17.551+0500] {subprocess.py:93} INFO -     sock = connection.create_connection(
[2023-11-29T21:41:17.567+0500] {subprocess.py:93} INFO -   File "/home/akashy/staidg/env/lib/python3.8/site-packages/urllib3/util/connection.py", line 85, in create_connection
[2023-11-29T21:41:17.572+0500] {subprocess.py:93} INFO -     raise err
[2023-11-29T21:41:17.574+0500] {subprocess.py:93} INFO -   File "/home/akashy/staidg/env/lib/python3.8/site-packages/urllib3/util/connection.py", line 73, in create_connection
[2023-11-29T21:41:17.577+0500] {subprocess.py:93} INFO -     sock.connect(sa)
[2023-11-29T21:41:17.588+0500] {subprocess.py:93} INFO - ConnectionRefusedError: [Errno 111] Connection refused
[2023-11-29T21:41:17.589+0500] {subprocess.py:93} INFO - 
[2023-11-29T21:41:17.601+0500] {subprocess.py:93} INFO - The above exception was the direct cause of the following exception:
[2023-11-29T21:41:17.638+0500] {subprocess.py:93} INFO - 
[2023-11-29T21:41:17.641+0500] {subprocess.py:93} INFO - Traceback (most recent call last):
[2023-11-29T21:41:17.648+0500] {subprocess.py:93} INFO -   File "/home/akashy/staidg/env/lib/python3.8/site-packages/urllib3/connectionpool.py", line 790, in urlopen
[2023-11-29T21:41:17.651+0500] {subprocess.py:93} INFO -     response = self._make_request(
[2023-11-29T21:41:17.652+0500] {subprocess.py:93} INFO -   File "/home/akashy/staidg/env/lib/python3.8/site-packages/urllib3/connectionpool.py", line 496, in _make_request
[2023-11-29T21:41:17.654+0500] {subprocess.py:93} INFO -     conn.request(
[2023-11-29T21:41:17.665+0500] {subprocess.py:93} INFO -   File "/home/akashy/staidg/env/lib/python3.8/site-packages/urllib3/connection.py", line 395, in request
[2023-11-29T21:41:17.666+0500] {subprocess.py:93} INFO -     self.endheaders()
[2023-11-29T21:41:17.671+0500] {subprocess.py:93} INFO -   File "/usr/lib/python3.8/http/client.py", line 1251, in endheaders
[2023-11-29T21:41:17.702+0500] {subprocess.py:93} INFO -     self._send_output(message_body, encode_chunked=encode_chunked)
[2023-11-29T21:41:17.703+0500] {subprocess.py:93} INFO -   File "/usr/lib/python3.8/http/client.py", line 1011, in _send_output
[2023-11-29T21:41:17.704+0500] {subprocess.py:93} INFO -     self.send(msg)
[2023-11-29T21:41:17.706+0500] {subprocess.py:93} INFO -   File "/usr/lib/python3.8/http/client.py", line 951, in send
[2023-11-29T21:41:17.722+0500] {subprocess.py:93} INFO -     self.connect()
[2023-11-29T21:41:17.723+0500] {subprocess.py:93} INFO -   File "/home/akashy/staidg/env/lib/python3.8/site-packages/urllib3/connection.py", line 243, in connect
[2023-11-29T21:41:17.724+0500] {subprocess.py:93} INFO -     self.sock = self._new_conn()
[2023-11-29T21:41:17.729+0500] {subprocess.py:93} INFO -   File "/home/akashy/staidg/env/lib/python3.8/site-packages/urllib3/connection.py", line 218, in _new_conn
[2023-11-29T21:41:17.740+0500] {subprocess.py:93} INFO -     raise NewConnectionError(
[2023-11-29T21:41:17.763+0500] {subprocess.py:93} INFO - urllib3.exceptions.NewConnectionError: <urllib3.connection.HTTPConnection object at 0x7f71f125b220>: Failed to establish a new connection: [Errno 111] Connection refused
[2023-11-29T21:41:17.765+0500] {subprocess.py:93} INFO - 
[2023-11-29T21:41:17.766+0500] {subprocess.py:93} INFO - The above exception was the direct cause of the following exception:
[2023-11-29T21:41:17.767+0500] {subprocess.py:93} INFO - 
[2023-11-29T21:41:17.768+0500] {subprocess.py:93} INFO - Traceback (most recent call last):
[2023-11-29T21:41:17.769+0500] {subprocess.py:93} INFO -   File "/home/akashy/staidg/env/lib/python3.8/site-packages/requests/adapters.py", line 486, in send
[2023-11-29T21:41:17.770+0500] {subprocess.py:93} INFO -     resp = conn.urlopen(
[2023-11-29T21:41:17.852+0500] {subprocess.py:93} INFO -   File "/home/akashy/staidg/env/lib/python3.8/site-packages/urllib3/connectionpool.py", line 874, in urlopen
[2023-11-29T21:41:17.853+0500] {subprocess.py:93} INFO -     return self.urlopen(
[2023-11-29T21:41:17.854+0500] {subprocess.py:93} INFO -   File "/home/akashy/staidg/env/lib/python3.8/site-packages/urllib3/connectionpool.py", line 874, in urlopen
[2023-11-29T21:41:17.855+0500] {subprocess.py:93} INFO -     return self.urlopen(
[2023-11-29T21:41:17.862+0500] {subprocess.py:93} INFO -   File "/home/akashy/staidg/env/lib/python3.8/site-packages/urllib3/connectionpool.py", line 874, in urlopen
[2023-11-29T21:41:17.879+0500] {subprocess.py:93} INFO -     return self.urlopen(
[2023-11-29T21:41:17.880+0500] {subprocess.py:93} INFO -   [Previous line repeated 2 more times]
[2023-11-29T21:41:17.885+0500] {subprocess.py:93} INFO -   File "/home/akashy/staidg/env/lib/python3.8/site-packages/urllib3/connectionpool.py", line 844, in urlopen
[2023-11-29T21:41:17.886+0500] {subprocess.py:93} INFO -     retries = retries.increment(
[2023-11-29T21:41:17.890+0500] {subprocess.py:93} INFO -   File "/home/akashy/staidg/env/lib/python3.8/site-packages/urllib3/util/retry.py", line 515, in increment
[2023-11-29T21:41:17.891+0500] {subprocess.py:93} INFO -     raise MaxRetryError(_pool, url, reason) from reason  # type: ignore[arg-type]
[2023-11-29T21:41:17.893+0500] {subprocess.py:93} INFO - urllib3.exceptions.MaxRetryError: HTTPConnectionPool(host='localhost', port=5000): Max retries exceeded with url: /api/2.0/mlflow/experiments/get-by-name?experiment_name=get_data (Caused by NewConnectionError('<urllib3.connection.HTTPConnection object at 0x7f71f125b220>: Failed to establish a new connection: [Errno 111] Connection refused'))
[2023-11-29T21:41:17.911+0500] {subprocess.py:93} INFO - 
[2023-11-29T21:41:17.913+0500] {subprocess.py:93} INFO - During handling of the above exception, another exception occurred:
[2023-11-29T21:41:17.914+0500] {subprocess.py:93} INFO - 
[2023-11-29T21:41:17.915+0500] {subprocess.py:93} INFO - Traceback (most recent call last):
[2023-11-29T21:41:17.916+0500] {subprocess.py:93} INFO -   File "/home/akashy/staidg/env/lib/python3.8/site-packages/mlflow/utils/rest_utils.py", line 99, in http_request
[2023-11-29T21:41:17.964+0500] {subprocess.py:93} INFO -     return _get_http_response_with_retries(
[2023-11-29T21:41:17.966+0500] {subprocess.py:93} INFO -   File "/home/akashy/staidg/env/lib/python3.8/site-packages/mlflow/utils/request_utils.py", line 151, in _get_http_response_with_retries
[2023-11-29T21:41:17.967+0500] {subprocess.py:93} INFO -     return session.request(method, url, **kwargs)
[2023-11-29T21:41:17.967+0500] {subprocess.py:93} INFO -   File "/home/akashy/staidg/env/lib/python3.8/site-packages/requests/sessions.py", line 589, in request
[2023-11-29T21:41:17.968+0500] {subprocess.py:93} INFO -     resp = self.send(prep, **send_kwargs)
[2023-11-29T21:41:17.969+0500] {subprocess.py:93} INFO -   File "/home/akashy/staidg/env/lib/python3.8/site-packages/requests/sessions.py", line 703, in send
[2023-11-29T21:41:17.970+0500] {subprocess.py:93} INFO -     r = adapter.send(request, **kwargs)
[2023-11-29T21:41:17.970+0500] {subprocess.py:93} INFO -   File "/home/akashy/staidg/env/lib/python3.8/site-packages/requests/adapters.py", line 519, in send
[2023-11-29T21:41:17.971+0500] {subprocess.py:93} INFO -     raise ConnectionError(e, request=request)
[2023-11-29T21:41:17.972+0500] {subprocess.py:93} INFO - requests.exceptions.ConnectionError: HTTPConnectionPool(host='localhost', port=5000): Max retries exceeded with url: /api/2.0/mlflow/experiments/get-by-name?experiment_name=get_data (Caused by NewConnectionError('<urllib3.connection.HTTPConnection object at 0x7f71f125b220>: Failed to establish a new connection: [Errno 111] Connection refused'))
[2023-11-29T21:41:17.973+0500] {subprocess.py:93} INFO - 
[2023-11-29T21:41:17.973+0500] {subprocess.py:93} INFO - During handling of the above exception, another exception occurred:
[2023-11-29T21:41:17.974+0500] {subprocess.py:93} INFO - 
[2023-11-29T21:41:17.975+0500] {subprocess.py:93} INFO - Traceback (most recent call last):
[2023-11-29T21:41:17.976+0500] {subprocess.py:93} INFO -   File "/home/akashy/staidg/scripts/get_data.py", line 11, in <module>
[2023-11-29T21:41:17.977+0500] {subprocess.py:93} INFO -     mlflow.set_experiment("get_data")
[2023-11-29T21:41:17.979+0500] {subprocess.py:93} INFO -   File "/home/akashy/staidg/env/lib/python3.8/site-packages/mlflow/tracking/fluent.py", line 135, in set_experiment
[2023-11-29T21:41:17.980+0500] {subprocess.py:93} INFO -     experiment = client.get_experiment_by_name(experiment_name)
[2023-11-29T21:41:17.981+0500] {subprocess.py:93} INFO -   File "/home/akashy/staidg/env/lib/python3.8/site-packages/mlflow/tracking/client.py", line 513, in get_experiment_by_name
[2023-11-29T21:41:17.982+0500] {subprocess.py:93} INFO -     return self._tracking_client.get_experiment_by_name(name)
[2023-11-29T21:41:17.983+0500] {subprocess.py:93} INFO -   File "/home/akashy/staidg/env/lib/python3.8/site-packages/mlflow/tracking/_tracking_service/client.py", line 221, in get_experiment_by_name
[2023-11-29T21:41:17.984+0500] {subprocess.py:93} INFO -     return self.store.get_experiment_by_name(name)
[2023-11-29T21:41:17.984+0500] {subprocess.py:93} INFO -   File "/home/akashy/staidg/env/lib/python3.8/site-packages/mlflow/store/tracking/rest_store.py", line 306, in get_experiment_by_name
[2023-11-29T21:41:17.985+0500] {subprocess.py:93} INFO -     response_proto = self._call_endpoint(GetExperimentByName, req_body)
[2023-11-29T21:41:17.986+0500] {subprocess.py:93} INFO -   File "/home/akashy/staidg/env/lib/python3.8/site-packages/mlflow/store/tracking/rest_store.py", line 59, in _call_endpoint
[2023-11-29T21:41:17.986+0500] {subprocess.py:93} INFO -     return call_endpoint(self.get_host_creds(), endpoint, method, json_body, response_proto)
[2023-11-29T21:41:17.987+0500] {subprocess.py:93} INFO -   File "/home/akashy/staidg/env/lib/python3.8/site-packages/mlflow/utils/rest_utils.py", line 206, in call_endpoint
[2023-11-29T21:41:17.987+0500] {subprocess.py:93} INFO -     response = http_request(**call_kwargs)
[2023-11-29T21:41:17.988+0500] {subprocess.py:93} INFO -   File "/home/akashy/staidg/env/lib/python3.8/site-packages/mlflow/utils/rest_utils.py", line 120, in http_request
[2023-11-29T21:41:17.989+0500] {subprocess.py:93} INFO -     raise MlflowException(f"API request to {url} failed with exception {e}")
[2023-11-29T21:41:18.006+0500] {subprocess.py:93} INFO - mlflow.exceptions.MlflowException: API request to http://localhost:5000/api/2.0/mlflow/experiments/get-by-name failed with exception HTTPConnectionPool(host='localhost', port=5000): Max retries exceeded with url: /api/2.0/mlflow/experiments/get-by-name?experiment_name=get_data (Caused by NewConnectionError('<urllib3.connection.HTTPConnection object at 0x7f71f125b220>: Failed to establish a new connection: [Errno 111] Connection refused'))
[2023-11-29T21:41:18.497+0500] {subprocess.py:97} INFO - Command exited with return code 1
[2023-11-29T21:41:18.747+0500] {taskinstance.py:1937} ERROR - Task failed with exception
Traceback (most recent call last):
  File "/home/akashy/staidg/env/lib/python3.8/site-packages/airflow/operators/bash.py", line 210, in execute
    raise AirflowException(
airflow.exceptions.AirflowException: Bash command failed. The command returned a non-zero exit code 1.
[2023-11-29T21:41:18.794+0500] {taskinstance.py:1400} INFO - Marking task as FAILED. dag_id=youtube_comments_score, task_id=get_data, execution_date=20231129T163320, start_date=20231129T164000, end_date=20231129T164118
[2023-11-29T21:41:18.908+0500] {standard_task_runner.py:104} ERROR - Failed to execute job 35 for task get_data (Bash command failed. The command returned a non-zero exit code 1.; 8573)
[2023-11-29T21:41:19.027+0500] {local_task_job_runner.py:228} INFO - Task exited with return code 1
[2023-11-29T21:41:19.154+0500] {taskinstance.py:2778} INFO - 0 downstream tasks scheduled from follow-on schedule check
