[2023-11-29T21:41:32.817+0500] {taskinstance.py:1159} INFO - Dependencies all met for dep_context=non-requeueable deps ti=<TaskInstance: youtube_comments_score.get_data manual__2023-11-29T16:39:43.036711+00:00 [queued]>
[2023-11-29T21:41:32.880+0500] {taskinstance.py:1159} INFO - Dependencies all met for dep_context=requeueable deps ti=<TaskInstance: youtube_comments_score.get_data manual__2023-11-29T16:39:43.036711+00:00 [queued]>
[2023-11-29T21:41:32.881+0500] {taskinstance.py:1361} INFO - Starting attempt 1 of 2
[2023-11-29T21:41:32.940+0500] {taskinstance.py:1382} INFO - Executing <Task(BashOperator): get_data> on 2023-11-29 16:39:43.036711+00:00
[2023-11-29T21:41:33.021+0500] {standard_task_runner.py:57} INFO - Started process 8864 to run task
[2023-11-29T21:41:33.034+0500] {standard_task_runner.py:84} INFO - Running: ['airflow', 'tasks', 'run', 'youtube_comments_score', 'get_data', 'manual__2023-11-29T16:39:43.036711+00:00', '--job-id', '36', '--raw', '--subdir', 'DAGS_FOLDER/youtube_comments_score.py', '--cfg-path', '/tmp/tmpmetd8u7l']
[2023-11-29T21:41:33.056+0500] {standard_task_runner.py:85} INFO - Job 36: Subtask get_data
[2023-11-29T21:41:33.903+0500] {task_command.py:416} INFO - Running <TaskInstance: youtube_comments_score.get_data manual__2023-11-29T16:39:43.036711+00:00 [running]> on host mlops
[2023-11-29T21:41:34.939+0500] {taskinstance.py:1662} INFO - Exporting env vars: AIRFLOW_CTX_DAG_OWNER='admin' AIRFLOW_CTX_DAG_ID='youtube_comments_score' AIRFLOW_CTX_TASK_ID='get_data' AIRFLOW_CTX_EXECUTION_DATE='2023-11-29T16:39:43.036711+00:00' AIRFLOW_CTX_TRY_NUMBER='1' AIRFLOW_CTX_DAG_RUN_ID='manual__2023-11-29T16:39:43.036711+00:00'
[2023-11-29T21:41:34.958+0500] {subprocess.py:63} INFO - Tmp dir root location: /tmp
[2023-11-29T21:41:34.979+0500] {subprocess.py:75} INFO - Running command: ['/usr/bin/bash', '-c', 'python3 /home/akashy/staidg/scripts/get_data.py']
[2023-11-29T21:41:35.242+0500] {subprocess.py:86} INFO - Output:
[2023-11-29T21:42:39.057+0500] {subprocess.py:93} INFO - /home/akashy/staidg/env/lib/python3.8/site-packages/pydantic/_internal/_fields.py:149: UserWarning: Field "model_server_url" has conflict with protected namespace "model_".
[2023-11-29T21:42:39.058+0500] {subprocess.py:93} INFO - 
[2023-11-29T21:42:39.059+0500] {subprocess.py:93} INFO - You may be able to resolve this warning by setting `model_config['protected_namespaces'] = ()`.
[2023-11-29T21:42:39.060+0500] {subprocess.py:93} INFO -   warnings.warn(
[2023-11-29T21:42:39.061+0500] {subprocess.py:93} INFO - /home/akashy/staidg/env/lib/python3.8/site-packages/pydantic/_internal/_config.py:321: UserWarning: Valid config keys have changed in V2:
[2023-11-29T21:42:39.062+0500] {subprocess.py:93} INFO - * 'schema_extra' has been renamed to 'json_schema_extra'
[2023-11-29T21:42:39.062+0500] {subprocess.py:93} INFO -   warnings.warn(message, UserWarning)
[2023-11-29T21:42:39.381+0500] {subprocess.py:93} INFO - Traceback (most recent call last):
[2023-11-29T21:42:39.381+0500] {subprocess.py:93} INFO -   File "/home/akashy/staidg/env/lib/python3.8/site-packages/urllib3/connection.py", line 203, in _new_conn
[2023-11-29T21:42:39.389+0500] {subprocess.py:93} INFO -     sock = connection.create_connection(
[2023-11-29T21:42:39.390+0500] {subprocess.py:93} INFO -   File "/home/akashy/staidg/env/lib/python3.8/site-packages/urllib3/util/connection.py", line 85, in create_connection
[2023-11-29T21:42:39.392+0500] {subprocess.py:93} INFO -     raise err
[2023-11-29T21:42:39.393+0500] {subprocess.py:93} INFO -   File "/home/akashy/staidg/env/lib/python3.8/site-packages/urllib3/util/connection.py", line 73, in create_connection
[2023-11-29T21:42:39.397+0500] {subprocess.py:93} INFO -     sock.connect(sa)
[2023-11-29T21:42:39.398+0500] {subprocess.py:93} INFO - ConnectionRefusedError: [Errno 111] Connection refused
[2023-11-29T21:42:39.398+0500] {subprocess.py:93} INFO - 
[2023-11-29T21:42:39.399+0500] {subprocess.py:93} INFO - The above exception was the direct cause of the following exception:
[2023-11-29T21:42:39.400+0500] {subprocess.py:93} INFO - 
[2023-11-29T21:42:39.401+0500] {subprocess.py:93} INFO - Traceback (most recent call last):
[2023-11-29T21:42:39.403+0500] {subprocess.py:93} INFO -   File "/home/akashy/staidg/env/lib/python3.8/site-packages/urllib3/connectionpool.py", line 790, in urlopen
[2023-11-29T21:42:39.404+0500] {subprocess.py:93} INFO -     response = self._make_request(
[2023-11-29T21:42:39.405+0500] {subprocess.py:93} INFO -   File "/home/akashy/staidg/env/lib/python3.8/site-packages/urllib3/connectionpool.py", line 496, in _make_request
[2023-11-29T21:42:39.406+0500] {subprocess.py:93} INFO -     conn.request(
[2023-11-29T21:42:39.407+0500] {subprocess.py:93} INFO -   File "/home/akashy/staidg/env/lib/python3.8/site-packages/urllib3/connection.py", line 395, in request
[2023-11-29T21:42:39.413+0500] {subprocess.py:93} INFO -     self.endheaders()
[2023-11-29T21:42:39.429+0500] {subprocess.py:93} INFO -   File "/usr/lib/python3.8/http/client.py", line 1251, in endheaders
[2023-11-29T21:42:39.430+0500] {subprocess.py:93} INFO -     self._send_output(message_body, encode_chunked=encode_chunked)
[2023-11-29T21:42:39.460+0500] {subprocess.py:93} INFO -   File "/usr/lib/python3.8/http/client.py", line 1011, in _send_output
[2023-11-29T21:42:39.470+0500] {subprocess.py:93} INFO -     self.send(msg)
[2023-11-29T21:42:39.487+0500] {subprocess.py:93} INFO -   File "/usr/lib/python3.8/http/client.py", line 951, in send
[2023-11-29T21:42:39.488+0500] {subprocess.py:93} INFO -     self.connect()
[2023-11-29T21:42:39.489+0500] {subprocess.py:93} INFO -   File "/home/akashy/staidg/env/lib/python3.8/site-packages/urllib3/connection.py", line 243, in connect
[2023-11-29T21:42:39.490+0500] {subprocess.py:93} INFO -     self.sock = self._new_conn()
[2023-11-29T21:42:39.492+0500] {subprocess.py:93} INFO -   File "/home/akashy/staidg/env/lib/python3.8/site-packages/urllib3/connection.py", line 218, in _new_conn
[2023-11-29T21:42:39.499+0500] {subprocess.py:93} INFO -     raise NewConnectionError(
[2023-11-29T21:42:39.500+0500] {subprocess.py:93} INFO - urllib3.exceptions.NewConnectionError: <urllib3.connection.HTTPConnection object at 0x7f9fcdd9bc70>: Failed to establish a new connection: [Errno 111] Connection refused
[2023-11-29T21:42:39.501+0500] {subprocess.py:93} INFO - 
[2023-11-29T21:42:39.502+0500] {subprocess.py:93} INFO - The above exception was the direct cause of the following exception:
[2023-11-29T21:42:39.503+0500] {subprocess.py:93} INFO - 
[2023-11-29T21:42:39.518+0500] {subprocess.py:93} INFO - Traceback (most recent call last):
[2023-11-29T21:42:39.519+0500] {subprocess.py:93} INFO -   File "/home/akashy/staidg/env/lib/python3.8/site-packages/requests/adapters.py", line 486, in send
[2023-11-29T21:42:39.520+0500] {subprocess.py:93} INFO -     resp = conn.urlopen(
[2023-11-29T21:42:39.521+0500] {subprocess.py:93} INFO -   File "/home/akashy/staidg/env/lib/python3.8/site-packages/urllib3/connectionpool.py", line 874, in urlopen
[2023-11-29T21:42:39.527+0500] {subprocess.py:93} INFO -     return self.urlopen(
[2023-11-29T21:42:39.528+0500] {subprocess.py:93} INFO -   File "/home/akashy/staidg/env/lib/python3.8/site-packages/urllib3/connectionpool.py", line 874, in urlopen
[2023-11-29T21:42:39.529+0500] {subprocess.py:93} INFO -     return self.urlopen(
[2023-11-29T21:42:39.536+0500] {subprocess.py:93} INFO -   File "/home/akashy/staidg/env/lib/python3.8/site-packages/urllib3/connectionpool.py", line 874, in urlopen
[2023-11-29T21:42:39.537+0500] {subprocess.py:93} INFO -     return self.urlopen(
[2023-11-29T21:42:39.538+0500] {subprocess.py:93} INFO -   [Previous line repeated 2 more times]
[2023-11-29T21:42:39.541+0500] {subprocess.py:93} INFO -   File "/home/akashy/staidg/env/lib/python3.8/site-packages/urllib3/connectionpool.py", line 844, in urlopen
[2023-11-29T21:42:39.543+0500] {subprocess.py:93} INFO -     retries = retries.increment(
[2023-11-29T21:42:39.552+0500] {subprocess.py:93} INFO -   File "/home/akashy/staidg/env/lib/python3.8/site-packages/urllib3/util/retry.py", line 515, in increment
[2023-11-29T21:42:39.553+0500] {subprocess.py:93} INFO -     raise MaxRetryError(_pool, url, reason) from reason  # type: ignore[arg-type]
[2023-11-29T21:42:39.554+0500] {subprocess.py:93} INFO - urllib3.exceptions.MaxRetryError: HTTPConnectionPool(host='localhost', port=5000): Max retries exceeded with url: /api/2.0/mlflow/experiments/get-by-name?experiment_name=get_data (Caused by NewConnectionError('<urllib3.connection.HTTPConnection object at 0x7f9fcdd9bc70>: Failed to establish a new connection: [Errno 111] Connection refused'))
[2023-11-29T21:42:39.555+0500] {subprocess.py:93} INFO - 
[2023-11-29T21:42:39.563+0500] {subprocess.py:93} INFO - During handling of the above exception, another exception occurred:
[2023-11-29T21:42:39.564+0500] {subprocess.py:93} INFO - 
[2023-11-29T21:42:39.565+0500] {subprocess.py:93} INFO - Traceback (most recent call last):
[2023-11-29T21:42:39.566+0500] {subprocess.py:93} INFO -   File "/home/akashy/staidg/env/lib/python3.8/site-packages/mlflow/utils/rest_utils.py", line 99, in http_request
[2023-11-29T21:42:39.571+0500] {subprocess.py:93} INFO -     return _get_http_response_with_retries(
[2023-11-29T21:42:39.573+0500] {subprocess.py:93} INFO -   File "/home/akashy/staidg/env/lib/python3.8/site-packages/mlflow/utils/request_utils.py", line 151, in _get_http_response_with_retries
[2023-11-29T21:42:39.574+0500] {subprocess.py:93} INFO -     return session.request(method, url, **kwargs)
[2023-11-29T21:42:39.576+0500] {subprocess.py:93} INFO -   File "/home/akashy/staidg/env/lib/python3.8/site-packages/requests/sessions.py", line 589, in request
[2023-11-29T21:42:39.585+0500] {subprocess.py:93} INFO -     resp = self.send(prep, **send_kwargs)
[2023-11-29T21:42:39.586+0500] {subprocess.py:93} INFO -   File "/home/akashy/staidg/env/lib/python3.8/site-packages/requests/sessions.py", line 703, in send
[2023-11-29T21:42:39.588+0500] {subprocess.py:93} INFO -     r = adapter.send(request, **kwargs)
[2023-11-29T21:42:39.589+0500] {subprocess.py:93} INFO -   File "/home/akashy/staidg/env/lib/python3.8/site-packages/requests/adapters.py", line 519, in send
[2023-11-29T21:42:39.591+0500] {subprocess.py:93} INFO -     raise ConnectionError(e, request=request)
[2023-11-29T21:42:39.594+0500] {subprocess.py:93} INFO - requests.exceptions.ConnectionError: HTTPConnectionPool(host='localhost', port=5000): Max retries exceeded with url: /api/2.0/mlflow/experiments/get-by-name?experiment_name=get_data (Caused by NewConnectionError('<urllib3.connection.HTTPConnection object at 0x7f9fcdd9bc70>: Failed to establish a new connection: [Errno 111] Connection refused'))
[2023-11-29T21:42:39.596+0500] {subprocess.py:93} INFO - 
[2023-11-29T21:42:39.598+0500] {subprocess.py:93} INFO - During handling of the above exception, another exception occurred:
[2023-11-29T21:42:39.600+0500] {subprocess.py:93} INFO - 
[2023-11-29T21:42:39.601+0500] {subprocess.py:93} INFO - Traceback (most recent call last):
[2023-11-29T21:42:39.603+0500] {subprocess.py:93} INFO -   File "/home/akashy/staidg/scripts/get_data.py", line 11, in <module>
[2023-11-29T21:42:39.604+0500] {subprocess.py:93} INFO -     mlflow.set_experiment("get_data")
[2023-11-29T21:42:39.605+0500] {subprocess.py:93} INFO -   File "/home/akashy/staidg/env/lib/python3.8/site-packages/mlflow/tracking/fluent.py", line 135, in set_experiment
[2023-11-29T21:42:39.607+0500] {subprocess.py:93} INFO -     experiment = client.get_experiment_by_name(experiment_name)
[2023-11-29T21:42:39.613+0500] {subprocess.py:93} INFO -   File "/home/akashy/staidg/env/lib/python3.8/site-packages/mlflow/tracking/client.py", line 513, in get_experiment_by_name
[2023-11-29T21:42:39.614+0500] {subprocess.py:93} INFO -     return self._tracking_client.get_experiment_by_name(name)
[2023-11-29T21:42:39.616+0500] {subprocess.py:93} INFO -   File "/home/akashy/staidg/env/lib/python3.8/site-packages/mlflow/tracking/_tracking_service/client.py", line 221, in get_experiment_by_name
[2023-11-29T21:42:39.617+0500] {subprocess.py:93} INFO -     return self.store.get_experiment_by_name(name)
[2023-11-29T21:42:39.618+0500] {subprocess.py:93} INFO -   File "/home/akashy/staidg/env/lib/python3.8/site-packages/mlflow/store/tracking/rest_store.py", line 306, in get_experiment_by_name
[2023-11-29T21:42:39.619+0500] {subprocess.py:93} INFO -     response_proto = self._call_endpoint(GetExperimentByName, req_body)
[2023-11-29T21:42:39.620+0500] {subprocess.py:93} INFO -   File "/home/akashy/staidg/env/lib/python3.8/site-packages/mlflow/store/tracking/rest_store.py", line 59, in _call_endpoint
[2023-11-29T21:42:39.621+0500] {subprocess.py:93} INFO -     return call_endpoint(self.get_host_creds(), endpoint, method, json_body, response_proto)
[2023-11-29T21:42:39.622+0500] {subprocess.py:93} INFO -   File "/home/akashy/staidg/env/lib/python3.8/site-packages/mlflow/utils/rest_utils.py", line 206, in call_endpoint
[2023-11-29T21:42:39.623+0500] {subprocess.py:93} INFO -     response = http_request(**call_kwargs)
[2023-11-29T21:42:39.625+0500] {subprocess.py:93} INFO -   File "/home/akashy/staidg/env/lib/python3.8/site-packages/mlflow/utils/rest_utils.py", line 120, in http_request
[2023-11-29T21:42:39.627+0500] {subprocess.py:93} INFO -     raise MlflowException(f"API request to {url} failed with exception {e}")
[2023-11-29T21:42:39.633+0500] {subprocess.py:93} INFO - mlflow.exceptions.MlflowException: API request to http://localhost:5000/api/2.0/mlflow/experiments/get-by-name failed with exception HTTPConnectionPool(host='localhost', port=5000): Max retries exceeded with url: /api/2.0/mlflow/experiments/get-by-name?experiment_name=get_data (Caused by NewConnectionError('<urllib3.connection.HTTPConnection object at 0x7f9fcdd9bc70>: Failed to establish a new connection: [Errno 111] Connection refused'))
[2023-11-29T21:42:39.768+0500] {subprocess.py:97} INFO - Command exited with return code 1
[2023-11-29T21:42:40.155+0500] {taskinstance.py:1937} ERROR - Task failed with exception
Traceback (most recent call last):
  File "/home/akashy/staidg/env/lib/python3.8/site-packages/airflow/operators/bash.py", line 210, in execute
    raise AirflowException(
airflow.exceptions.AirflowException: Bash command failed. The command returned a non-zero exit code 1.
[2023-11-29T21:42:40.173+0500] {taskinstance.py:1400} INFO - Marking task as UP_FOR_RETRY. dag_id=youtube_comments_score, task_id=get_data, execution_date=20231129T163943, start_date=20231129T164132, end_date=20231129T164240
[2023-11-29T21:42:40.325+0500] {standard_task_runner.py:104} ERROR - Failed to execute job 36 for task get_data (Bash command failed. The command returned a non-zero exit code 1.; 8864)
[2023-11-29T21:42:40.638+0500] {local_task_job_runner.py:228} INFO - Task exited with return code 1
[2023-11-29T21:42:41.277+0500] {taskinstance.py:2778} INFO - 0 downstream tasks scheduled from follow-on schedule check
