[2023-11-30T12:09:39.256+0500] {taskinstance.py:1159} INFO - Dependencies all met for dep_context=non-requeueable deps ti=<TaskInstance: youtube_comments_score.process_data manual__2023-11-30T07:07:50.762429+00:00 [queued]>
[2023-11-30T12:09:39.275+0500] {taskinstance.py:1159} INFO - Dependencies all met for dep_context=requeueable deps ti=<TaskInstance: youtube_comments_score.process_data manual__2023-11-30T07:07:50.762429+00:00 [queued]>
[2023-11-30T12:09:39.276+0500] {taskinstance.py:1361} INFO - Starting attempt 1 of 2
[2023-11-30T12:09:39.325+0500] {taskinstance.py:1382} INFO - Executing <Task(BashOperator): process_data> on 2023-11-30 07:07:50.762429+00:00
[2023-11-30T12:09:39.340+0500] {standard_task_runner.py:57} INFO - Started process 4453 to run task
[2023-11-30T12:09:39.349+0500] {standard_task_runner.py:84} INFO - Running: ['airflow', 'tasks', 'run', 'youtube_comments_score', 'process_data', 'manual__2023-11-30T07:07:50.762429+00:00', '--job-id', '46', '--raw', '--subdir', 'DAGS_FOLDER/youtube_comments_score.py', '--cfg-path', '/tmp/tmp81bztm42']
[2023-11-30T12:09:39.357+0500] {standard_task_runner.py:85} INFO - Job 46: Subtask process_data
[2023-11-30T12:09:39.610+0500] {task_command.py:416} INFO - Running <TaskInstance: youtube_comments_score.process_data manual__2023-11-30T07:07:50.762429+00:00 [running]> on host mlops
[2023-11-30T12:09:39.970+0500] {taskinstance.py:1662} INFO - Exporting env vars: AIRFLOW_CTX_DAG_OWNER='admin' AIRFLOW_CTX_DAG_ID='youtube_comments_score' AIRFLOW_CTX_TASK_ID='process_data' AIRFLOW_CTX_EXECUTION_DATE='2023-11-30T07:07:50.762429+00:00' AIRFLOW_CTX_TRY_NUMBER='1' AIRFLOW_CTX_DAG_RUN_ID='manual__2023-11-30T07:07:50.762429+00:00'
[2023-11-30T12:09:39.974+0500] {subprocess.py:63} INFO - Tmp dir root location: /tmp
[2023-11-30T12:09:39.975+0500] {subprocess.py:75} INFO - Running command: ['/usr/bin/bash', '-c', 'python3 /home/akashy/staidg/scripts/process_data.py']
[2023-11-30T12:09:40.024+0500] {subprocess.py:86} INFO - Output:
[2023-11-30T12:09:41.115+0500] {subprocess.py:93} INFO - Traceback (most recent call last):
[2023-11-30T12:09:41.116+0500] {subprocess.py:93} INFO -   File "/home/akashy/staidg/env/lib/python3.8/site-packages/pandas/core/indexes/base.py", line 3653, in get_loc
[2023-11-30T12:09:41.120+0500] {subprocess.py:93} INFO -     return self._engine.get_loc(casted_key)
[2023-11-30T12:09:41.127+0500] {subprocess.py:93} INFO -   File "pandas/_libs/index.pyx", line 147, in pandas._libs.index.IndexEngine.get_loc
[2023-11-30T12:09:41.133+0500] {subprocess.py:93} INFO -   File "pandas/_libs/index.pyx", line 155, in pandas._libs.index.IndexEngine.get_loc
[2023-11-30T12:09:41.134+0500] {subprocess.py:93} INFO -   File "pandas/_libs/index_class_helper.pxi", line 70, in pandas._libs.index.Int64Engine._check_type
[2023-11-30T12:09:41.135+0500] {subprocess.py:93} INFO - KeyError: 'id'
[2023-11-30T12:09:41.136+0500] {subprocess.py:93} INFO - 
[2023-11-30T12:09:41.137+0500] {subprocess.py:93} INFO - The above exception was the direct cause of the following exception:
[2023-11-30T12:09:41.137+0500] {subprocess.py:93} INFO - 
[2023-11-30T12:09:41.138+0500] {subprocess.py:93} INFO - Traceback (most recent call last):
[2023-11-30T12:09:41.138+0500] {subprocess.py:93} INFO -   File "/home/akashy/staidg/scripts/process_data.py", line 5, in <module>
[2023-11-30T12:09:41.139+0500] {subprocess.py:93} INFO -     for i in range(len(df['id'])):
[2023-11-30T12:09:41.140+0500] {subprocess.py:93} INFO -   File "/home/akashy/staidg/env/lib/python3.8/site-packages/pandas/core/frame.py", line 3761, in __getitem__
[2023-11-30T12:09:41.140+0500] {subprocess.py:93} INFO -     indexer = self.columns.get_loc(key)
[2023-11-30T12:09:41.141+0500] {subprocess.py:93} INFO -   File "/home/akashy/staidg/env/lib/python3.8/site-packages/pandas/core/indexes/base.py", line 3655, in get_loc
[2023-11-30T12:09:41.141+0500] {subprocess.py:93} INFO -     raise KeyError(key) from err
[2023-11-30T12:09:41.142+0500] {subprocess.py:93} INFO - KeyError: 'id'
[2023-11-30T12:09:41.312+0500] {subprocess.py:97} INFO - Command exited with return code 1
[2023-11-30T12:09:41.385+0500] {taskinstance.py:1937} ERROR - Task failed with exception
Traceback (most recent call last):
  File "/home/akashy/staidg/env/lib/python3.8/site-packages/airflow/operators/bash.py", line 210, in execute
    raise AirflowException(
airflow.exceptions.AirflowException: Bash command failed. The command returned a non-zero exit code 1.
[2023-11-30T12:09:41.395+0500] {taskinstance.py:1400} INFO - Marking task as UP_FOR_RETRY. dag_id=youtube_comments_score, task_id=process_data, execution_date=20231130T070750, start_date=20231130T070939, end_date=20231130T070941
[2023-11-30T12:09:41.450+0500] {standard_task_runner.py:104} ERROR - Failed to execute job 46 for task process_data (Bash command failed. The command returned a non-zero exit code 1.; 4453)
[2023-11-30T12:09:41.512+0500] {local_task_job_runner.py:228} INFO - Task exited with return code 1
[2023-11-30T12:09:41.612+0500] {taskinstance.py:2778} INFO - 0 downstream tasks scheduled from follow-on schedule check
